{
    (import "Functional/Exceptions.ark")

    (let exception-tests (fun () {
        (let invert (fun (x) {
            (if (= x 0)
                (throw "cannot divide by zero")
                (return (/ 1 x))
            )
        }))

        (try (invert 0)
            (fun (inverted) (assert false "Exception test 1 failed"))
            (fun (err) (assert (= err "cannot divide by zero") "Exception test 1Â°2 failed"))
        )
        
        (print "  Exception tests passed")
    }))

    (exception-tests)
}